<?xml version="1.0"?>
<robot name="collision">

  <material name="blue">
    <color rgba="0 0 0.8 1"/>
  </material>

  <material name="white">
    <color rgba="1 1 1 1"/>
  </material>

  <material name="red">
    <color rgba="1 0 0 1"/>
  </material>

  <link name="base_link">
    <visual>
      <origin xyz="0 0 1" rpy="0 0 0"/>
      <geometry>
        <box size="0.1 0.1 2"/>
      </geometry>
      <material name="blue"/>
    </visual>

    <collision>
      <origin xyz="0 0 1" rpy="0 0 0"/>
      <geometry>
	      <box size="0.1 0.1 2"/>
      </geometry>
    </collision>  

    <inertial>
      <origin xyz="0 0 0.5" rpy="0 0 0"/>
      <mass value="2"/>
      <inertia ixx="0.08" ixy="0.0" ixz="0.0" iyy="0.08" iyz="0.0" izz="0.001"/>
    </inertial>
  </link>

  <joint name="joint1" type="continuous">
    <parent link="base_link"/>
    <child link="link2"/>
    <origin xyz="0 0.1 1.95" rpy="0 0 0"/>
    <axis xyz="0 1 0"/>
  </joint>

  <link name="link2">
    <visual>
      <origin xyz="0 0 0.45" rpy="0 0 0"/>
      <geometry>
        <box size="0.1 0.1 1"/>
      </geometry>
      <material name="white"/>
    </visual>

    <collision>
      <origin xyz="0 0 0.45" rpy="0 0 0"/>
      <geometry>
	      <box size="0.1 0.1 1"/>
      </geometry>
    </collision>

    <inertial>
      <origin xyz="0 0 0.5" rpy="0 0 0"/>
      <mass value="1"/>
      <inertia ixx="0.08" ixy="0.0" ixz="0.0" iyy="0.08" iyz="0.0" izz="0.001"/>
    </inertial>
  </link>

  <joint name="joint2" type="continuous">
    <parent link="link2"/>
    <child link="link3"/>
    <origin xyz="0 0.1 0.90" rpy="0 0 0"/>
    <axis xyz="0 1 0"/>
  </joint>

    <link name="link3">
    <visual>
      <origin xyz="0 0 0.45" rpy="0 0 0"/>
      <geometry>
        <box size="0.1 0.1 1"/>
      </geometry>
      <material name="red"/>
    </visual>

    <collision>
      <origin xyz="0 0 0.45" rpy="0 0 0"/>
      <geometry>
	      <box size="0.1 0.1 1"/>
      </geometry>
    </collision>
  
    <inertial>
      <origin xyz="0 0 0.5" rpy="0 0 0"/>
      <mass value="1"/>
      <inertia ixx="0.08" ixy="0.0" ixz="0.0" iyy="0.08" iyz="0.0" izz="0.001"/>
    </inertial>
  </link>

</robot>

