<?xml version="1.0"?>
<robot name="macroed" xmlns:xacro="http://ros.org/wiki/xacro">

  <xacro:property name="width" value="0.1" />
  <xacro:property name="height1" value="2" />
  <xacro:property name="height2" value="1" />
  <xacro:property name="constant" value="0.45" />

  <xacro:macro name="default_inertial" params="mass">
    <inertial>
      <mass value="${mass}" />
     <inertia ixx="0.08" ixy="0.0" ixz="0.0" iyy="0.08" iyz="0.0" izz="0.001"/>
    </inertial>
  </xacro:macro>

   <material name="blue">
    <color rgba="0 0 0.8 1"/>
  </material>

  <material name="white">
    <color rgba="1 1 1 1"/>
  </material>

  <material name="red">
    <color rgba="1 0 0 1"/>
  </material>

  <link name="base_link">
    <visual>
      <origin xyz="0 0 1" rpy="0 0 0"/>
      <geometry>
        <box size="${width} ${width} ${height1}"/>
      </geometry>
      <material name="blue"/>
    </visual>

    <collision>
      <origin xyz="0 0 1" rpy="0 0 0"/>
      <geometry>
	      <box size="${width} ${width} ${height1}"/>
      </geometry>
    </collision>  

    <xacro:default_inertial mass="2"/>
  </link>

  <joint name="joint1" type="continuous">
    <parent link="base_link"/>
    <child link="link2"/>
    <origin xyz="0 0.1 1.95" rpy="0 0 0"/>
    <axis xyz="0 1 0"/>
  </joint>

  <link name="link2">
    <visual>
      <origin xyz="0 0 0.45" rpy="0 0 0"/>
      <geometry>
        <box size="${width} ${width} ${height2}"/>
      </geometry>
      <material name="white"/>
    </visual>

    <collision>
      <origin xyz="0 0 0.45" rpy="0 0 0"/>
      <geometry>
	      <box size="${width} ${width} ${height2}"/>
      </geometry>
    </collision>

    <xacro:default_inertial mass="1"/>
  </link>

  <joint name="joint2" type="continuous">
    <parent link="link2"/>
    <child link="link3"/>
    <origin xyz="0 0.1 0.90" rpy="0 0 0"/>
    <axis xyz="0 1 0"/>
  </joint>

    <link name="link3">
    <visual>
      <origin xyz="0 0 0.45" rpy="0 0 0"/>
      <geometry>
        <box size="${width} ${width} ${height2}"/>
      </geometry>
      <material name="red"/>
    </visual>

    <collision>
      <origin xyz="0 0 0.45" rpy="0 0 0"/>
      <geometry>
	      <box size="${width} ${width} ${height2}"/>
      </geometry>
    </collision>
  
    <xacro:default_inertial mass="1"/>
  </link>

</robot>
